{
  "health_status": {
    "overall_status": "critical",
    "timestamp": "2025-08-29T23:47:21.223648",
    "system_metrics": {
      "timestamp": "2025-08-29T23:47:21.201175",
      "cpu_percent": 17.5,
      "memory_percent": 81.9,
      "memory_available_gb": 1.45,
      "disk_usage_percent": 6.01,
      "disk_free_gb": 16.14,
      "network_bytes_sent": 2675869696,
      "network_bytes_recv": 2736753664
    },
    "api_metrics": {
      "tested_endpoints": 6,
      "successful": 0,
      "failed": 6,
      "average_response_time": 0.0,
      "endpoint_results": [
        {
          "endpoint": "GET /health",
          "response_time_ms": 0,
          "status_code": 0,
          "success": false,
          "error": "HTTPConnectionPool(host='localhost', port=8080): Max retries exceeded with url: /health (Caused by NewConnectionError('<urllib3.connection.HTTPConnection object at 0x106d883e0>: Failed to establish a new connection: [Errno 61] Connection refused'))"
        },
        {
          "endpoint": "GET /api/status",
          "response_time_ms": 0,
          "status_code": 0,
          "success": false,
          "error": "HTTPConnectionPool(host='localhost', port=8080): Max retries exceeded with url: /api/status (Caused by NewConnectionError('<urllib3.connection.HTTPConnection object at 0x1057c22d0>: Failed to establish a new connection: [Errno 61] Connection refused'))"
        },
        {
          "endpoint": "GET /patients/",
          "response_time_ms": 0,
          "status_code": 0,
          "success": false,
          "error": "HTTPConnectionPool(host='localhost', port=8080): Max retries exceeded with url: /patients/ (Caused by NewConnectionError('<urllib3.connection.HTTPConnection object at 0x106d88350>: Failed to establish a new connection: [Errno 61] Connection refused'))"
        },
        {
          "endpoint": "GET /intake/all-patients",
          "response_time_ms": 0,
          "status_code": 0,
          "success": false,
          "error": "HTTPConnectionPool(host='localhost', port=8080): Max retries exceeded with url: /intake/all-patients (Caused by NewConnectionError('<urllib3.connection.HTTPConnection object at 0x106d890a0>: Failed to establish a new connection: [Errno 61] Connection refused'))"
        },
        {
          "endpoint": "GET /hbys/health",
          "response_time_ms": 0,
          "status_code": 0,
          "success": false,
          "error": "HTTPConnectionPool(host='localhost', port=8080): Max retries exceeded with url: /hbys/health (Caused by NewConnectionError('<urllib3.connection.HTTPConnection object at 0x106d896d0>: Failed to establish a new connection: [Errno 61] Connection refused'))"
        },
        {
          "endpoint": "GET /monai/models",
          "response_time_ms": 0,
          "status_code": 0,
          "success": false,
          "error": "HTTPConnectionPool(host='localhost', port=8080): Max retries exceeded with url: /monai/models (Caused by NewConnectionError('<urllib3.connection.HTTPConnection object at 0x106d89f70>: Failed to establish a new connection: [Errno 61] Connection refused'))"
        }
      ],
      "success_rate": 0.0
    },
    "warnings": [
      "Elevated memory usage"
    ],
    "errors": [
      "Multiple API endpoints failing"
    ],
    "uptime_hours": 139.26
  },
  "performance_report": {
    "report_timestamp": "2025-08-29T23:47:22.246847",
    "overall_performance": {
      "score": 50,
      "grade": "F",
      "status": "critical"
    },
    "current_metrics": {
      "system": {
        "timestamp": "2025-08-29T23:47:22.228821",
        "cpu_percent": 19.3,
        "memory_percent": 81.4,
        "memory_available_gb": 1.48,
        "disk_usage_percent": 6.01,
        "disk_free_gb": 16.14,
        "network_bytes_sent": 2675902464,
        "network_bytes_recv": 2736771072
      },
      "api": {
        "tested_endpoints": 6,
        "successful": 0,
        "failed": 6,
        "average_response_time": 0.0,
        "endpoint_results": [
          {
            "endpoint": "GET /health",
            "response_time_ms": 0,
            "status_code": 0,
            "success": false,
            "error": "HTTPConnectionPool(host='localhost', port=8080): Max retries exceeded with url: /health (Caused by NewConnectionError('<urllib3.connection.HTTPConnection object at 0x106d8a150>: Failed to establish a new connection: [Errno 61] Connection refused'))"
          },
          {
            "endpoint": "GET /api/status",
            "response_time_ms": 0,
            "status_code": 0,
            "success": false,
            "error": "HTTPConnectionPool(host='localhost', port=8080): Max retries exceeded with url: /api/status (Caused by NewConnectionError('<urllib3.connection.HTTPConnection object at 0x106d89a00>: Failed to establish a new connection: [Errno 61] Connection refused'))"
          },
          {
            "endpoint": "GET /patients/",
            "response_time_ms": 0,
            "status_code": 0,
            "success": false,
            "error": "HTTPConnectionPool(host='localhost', port=8080): Max retries exceeded with url: /patients/ (Caused by NewConnectionError('<urllib3.connection.HTTPConnection object at 0x106d88ec0>: Failed to establish a new connection: [Errno 61] Connection refused'))"
          },
          {
            "endpoint": "GET /intake/all-patients",
            "response_time_ms": 0,
            "status_code": 0,
            "success": false,
            "error": "HTTPConnectionPool(host='localhost', port=8080): Max retries exceeded with url: /intake/all-patients (Caused by NewConnectionError('<urllib3.connection.HTTPConnection object at 0x106d88830>: Failed to establish a new connection: [Errno 61] Connection refused'))"
          },
          {
            "endpoint": "GET /hbys/health",
            "response_time_ms": 0,
            "status_code": 0,
            "success": false,
            "error": "HTTPConnectionPool(host='localhost', port=8080): Max retries exceeded with url: /hbys/health (Caused by NewConnectionError('<urllib3.connection.HTTPConnection object at 0x106d8a8d0>: Failed to establish a new connection: [Errno 61] Connection refused'))"
          },
          {
            "endpoint": "GET /monai/models",
            "response_time_ms": 0,
            "status_code": 0,
            "success": false,
            "error": "HTTPConnectionPool(host='localhost', port=8080): Max retries exceeded with url: /monai/models (Caused by NewConnectionError('<urllib3.connection.HTTPConnection object at 0x106d53a10>: Failed to establish a new connection: [Errno 61] Connection refused'))"
          }
        ],
        "success_rate": 0.0
      }
    },
    "historical_summary": {
      "data_points": 2,
      "api_endpoints_monitored": 0,
      "recent_errors_count": 12
    },
    "recommendations": [
      "Monitor memory leaks and consider increasing RAM or implementing caching",
      "Investigate failing API endpoints and implement better error handling",
      "Address critical system errors to improve stability"
    ]
  },
  "historical_data": {
    "time_range_hours": 6,
    "system_history": [
      {
        "timestamp": "2025-08-29 20:47:22",
        "cpu_percent": 19.3,
        "memory_percent": 81.4,
        "disk_usage_percent": 6.01
      },
      {
        "timestamp": "2025-08-29 20:47:21",
        "cpu_percent": 17.5,
        "memory_percent": 81.9,
        "disk_usage_percent": 6.01
      }
    ],
    "api_history": [],
    "recent_errors": [
      {
        "timestamp": "2025-08-29 20:47:22",
        "error_type": "API_TEST",
        "error_message": "HTTPConnectionPool(host='localhost', port=8080): Max retries exceeded with url: /health (Caused by NewConnectionError('<urllib3.connection.HTTPConnection object at 0x106d8a150>: Failed to establish a new connection: [Errno 61] Connection refused'))",
        "source": "GET /health",
        "severity": "ERROR"
      },
      {
        "timestamp": "2025-08-29 20:47:22",
        "error_type": "API_TEST",
        "error_message": "HTTPConnectionPool(host='localhost', port=8080): Max retries exceeded with url: /api/status (Caused by NewConnectionError('<urllib3.connection.HTTPConnection object at 0x106d89a00>: Failed to establish a new connection: [Errno 61] Connection refused'))",
        "source": "GET /api/status",
        "severity": "ERROR"
      },
      {
        "timestamp": "2025-08-29 20:47:22",
        "error_type": "API_TEST",
        "error_message": "HTTPConnectionPool(host='localhost', port=8080): Max retries exceeded with url: /patients/ (Caused by NewConnectionError('<urllib3.connection.HTTPConnection object at 0x106d88ec0>: Failed to establish a new connection: [Errno 61] Connection refused'))",
        "source": "GET /patients/",
        "severity": "ERROR"
      },
      {
        "timestamp": "2025-08-29 20:47:22",
        "error_type": "API_TEST",
        "error_message": "HTTPConnectionPool(host='localhost', port=8080): Max retries exceeded with url: /intake/all-patients (Caused by NewConnectionError('<urllib3.connection.HTTPConnection object at 0x106d88830>: Failed to establish a new connection: [Errno 61] Connection refused'))",
        "source": "GET /intake/all-patients",
        "severity": "ERROR"
      },
      {
        "timestamp": "2025-08-29 20:47:22",
        "error_type": "API_TEST",
        "error_message": "HTTPConnectionPool(host='localhost', port=8080): Max retries exceeded with url: /hbys/health (Caused by NewConnectionError('<urllib3.connection.HTTPConnection object at 0x106d8a8d0>: Failed to establish a new connection: [Errno 61] Connection refused'))",
        "source": "GET /hbys/health",
        "severity": "ERROR"
      },
      {
        "timestamp": "2025-08-29 20:47:22",
        "error_type": "API_TEST",
        "error_message": "HTTPConnectionPool(host='localhost', port=8080): Max retries exceeded with url: /monai/models (Caused by NewConnectionError('<urllib3.connection.HTTPConnection object at 0x106d53a10>: Failed to establish a new connection: [Errno 61] Connection refused'))",
        "source": "GET /monai/models",
        "severity": "ERROR"
      },
      {
        "timestamp": "2025-08-29 20:47:21",
        "error_type": "API_TEST",
        "error_message": "HTTPConnectionPool(host='localhost', port=8080): Max retries exceeded with url: /health (Caused by NewConnectionError('<urllib3.connection.HTTPConnection object at 0x106d883e0>: Failed to establish a new connection: [Errno 61] Connection refused'))",
        "source": "GET /health",
        "severity": "ERROR"
      },
      {
        "timestamp": "2025-08-29 20:47:21",
        "error_type": "API_TEST",
        "error_message": "HTTPConnectionPool(host='localhost', port=8080): Max retries exceeded with url: /api/status (Caused by NewConnectionError('<urllib3.connection.HTTPConnection object at 0x1057c22d0>: Failed to establish a new connection: [Errno 61] Connection refused'))",
        "source": "GET /api/status",
        "severity": "ERROR"
      },
      {
        "timestamp": "2025-08-29 20:47:21",
        "error_type": "API_TEST",
        "error_message": "HTTPConnectionPool(host='localhost', port=8080): Max retries exceeded with url: /patients/ (Caused by NewConnectionError('<urllib3.connection.HTTPConnection object at 0x106d88350>: Failed to establish a new connection: [Errno 61] Connection refused'))",
        "source": "GET /patients/",
        "severity": "ERROR"
      },
      {
        "timestamp": "2025-08-29 20:47:21",
        "error_type": "API_TEST",
        "error_message": "HTTPConnectionPool(host='localhost', port=8080): Max retries exceeded with url: /intake/all-patients (Caused by NewConnectionError('<urllib3.connection.HTTPConnection object at 0x106d890a0>: Failed to establish a new connection: [Errno 61] Connection refused'))",
        "source": "GET /intake/all-patients",
        "severity": "ERROR"
      },
      {
        "timestamp": "2025-08-29 20:47:21",
        "error_type": "API_TEST",
        "error_message": "HTTPConnectionPool(host='localhost', port=8080): Max retries exceeded with url: /hbys/health (Caused by NewConnectionError('<urllib3.connection.HTTPConnection object at 0x106d896d0>: Failed to establish a new connection: [Errno 61] Connection refused'))",
        "source": "GET /hbys/health",
        "severity": "ERROR"
      },
      {
        "timestamp": "2025-08-29 20:47:21",
        "error_type": "API_TEST",
        "error_message": "HTTPConnectionPool(host='localhost', port=8080): Max retries exceeded with url: /monai/models (Caused by NewConnectionError('<urllib3.connection.HTTPConnection object at 0x106d89f70>: Failed to establish a new connection: [Errno 61] Connection refused'))",
        "source": "GET /monai/models",
        "severity": "ERROR"
      }
    ],
    "generated_at": "2025-08-29T23:47:22.247444"
  }
}